Exception in thread Thread-1:
Traceback (most recent call last):
  File "/home/yy/anaconda3/lib/python3.8/threading.py", line 932, in _bootstrap_inner
    self.run()
  File "/home/yy/anaconda3/lib/python3.8/threading.py", line 870, in run
    self._target(*self._args, **self._kwargs)
  File "main.py", line 43, in thread_loop_task
Exception in thread Thread-2:
Traceback (most recent call last):
  File "/home/yy/anaconda3/lib/python3.8/threading.py", line 932, in _bootstrap_inner
    loop.run_until_complete(start_server)
  File "/home/yy/anaconda3/lib/python3.8/asyncio/base_events.py", line 616, in run_until_complete
    return future.result()
  File "/home/yy/anaconda3/lib/python3.8/asyncio/tasks.py", line 684, in _wrap_awaitable
    self.run()
  File "/home/yy/anaconda3/lib/python3.8/threading.py", line 870, in run
    self._target(*self._args, **self._kwargs)
  File "main.py", line 43, in thread_loop_task
    return (yield from awaitable.__await__())
  File "/home/yy/anaconda3/lib/python3.8/site-packages/websockets/server.py", line 965, in __await_impl__
    loop.run_until_complete(start_server)
  File "/home/yy/anaconda3/lib/python3.8/asyncio/base_events.py", line 616, in run_until_complete
    return future.result()
  File "/home/yy/anaconda3/lib/python3.8/asyncio/tasks.py", line 684, in _wrap_awaitable
    server = await self._create_server()
  File "/home/yy/anaconda3/lib/python3.8/asyncio/base_events.py", line 1463, in create_server
    return (yield from awaitable.__await__())
  File "/home/yy/anaconda3/lib/python3.8/site-packages/websockets/server.py", line 965, in __await_impl__
    server = await self._create_server()
  File "/home/yy/anaconda3/lib/python3.8/asyncio/base_events.py", line 1463, in create_server
    raise OSError(err.errno, 'error while attempting '
OSError: [Errno 98] error while attempting to bind on address ('0.0.0.0', 5679): address already in use
    raise OSError(err.errno, 'error while attempting '
OSError: [Errno 98] error while attempting to bind on address ('0.0.0.0', 5678): address already in use
